#VRML_SIM R2023b utf8

EXTERNPROTO "https://raw.githubusercontent.com/cyberbotics/webots/R2023b/projects/robots/gctronic/e-puck/protos/E-puckDistanceSensor.proto"
EXTERNPROTO "https://raw.githubusercontent.com/cyberbotics/webots/R2023b/projects/robots/nvidia/jetbot/protos/JetBotRaspberryPiCamera.proto"
EXTERNPROTO "https://raw.githubusercontent.com/cyberbotics/webots/R2023b/projects/robots/mir/mir100/protos/Mir100UltrasonicSensor.proto"

PROTO AutoNova [
  field SFVec3f            translation                  0 0 0
  field SFRotation         rotation                     0 0 1 0
  field SFString           name                         "AutoNova"
  field SFString           model                        "v1"
  field SFString           controller                   "<generic>"
]
{
Robot {
  translation IS translation
  rotation IS rotation
  children [
    Mir100UltrasonicSensor {
      translation -0.073 0 0.009
      rotation 0 0 1 3.14159
      name "ps8"
    }
    Mir100UltrasonicSensor {
      translation -0.05 0.05 0.041
      rotation 0 0 1 1.5708
      name "ps7"
    }
    Mir100UltrasonicSensor {
      translation -0.05 -0.05 0.041
      rotation 0 0 1 -1.5708
      name "ps5"
    }
    Mir100UltrasonicSensor {
      translation 0.05 -0.05 0.041
      rotation 0 0 1 -1.5708
      name "ps3"
    }
    Mir100UltrasonicSensor {
      translation 0.05 0.05 0.041
      rotation 0 0 1 1.5708
      name "ps1"
    }
    GPS {
      name "GPS"
    }
    Mir100UltrasonicSensor {
      translation 0 -0.073 0.009
      rotation 0 0 1 -1.5708
      name "ps0"
    }
    Mir100UltrasonicSensor {
      translation 0 0.073 0.009
      rotation 0 0 1 1.5708
      name "ps4"
    }
    Mir100UltrasonicSensor {
      translation 0.073 0 0.041
      name "ps2"
    }
    Gyro {
      name "gyroScope"
    }
    InertialUnit {
      name "Inertial Unit"
    }
    SpotLight {
      attenuation 0 0 0.4
      beamWidth 0.7
      direction 1 0 0
      intensity 0.2
    }
    JetBotRaspberryPiCamera {
      translation 0.06 0 0.005
      fieldOfView 2
      width 360
      height 360
    }
    HingeJoint {
      jointParameters HingeJointParameters {
        position 55.201639954134855
        axis 0 1 0
        anchor 0 0.06 0.0098
      }
      device [
        PositionSensor {
          name "left encoder"
        }
        RotationalMotor {
          name "left motor"
        }
      ]
      endPoint Solid {
        translation 0 0.06 0.0098
        rotation -0.663201978740694 0.5292263588492966 -0.5292283028084793 4.312789542383721
        children [
          DEF wheel Shape {
            appearance PBRAppearance {
              baseColor 0 1 1
              metalness 0
            }
            geometry DEF wheel_geo Cylinder {
              height 0.009
              radius 0.03
            }
          }
        ]
        name "LeftWheel"
        boundingObject USE wheel
        physics Physics {
        }
      }
    }
    HingeJoint {
      jointParameters HingeJointParameters {
        position 55.201639892140776
        axis 0 1 0
        anchor 0 -0.06 0.0098
      }
      device [
        PositionSensor {
          name "right encoder"
        }
        RotationalMotor {
          name "right motor"
        }
      ]
      endPoint Solid {
        translation 0 -0.06 0.0098
        rotation -0.6632019550735453 0.5292263736785301 -0.5292283176377659 4.312789509509007
        children [
          DEF wheel Shape {
            appearance PBRAppearance {
              baseColor 0 1 1
              metalness 0
            }
            geometry DEF wheel_geo Cylinder {
              height 0.009
              radius 0.03
            }
          }
        ]
        name "RightWheel"
        boundingObject USE wheel
        physics DEF physics_wh Physics {
        }
      }
    }
    DEF Body Shape {
      appearance PBRAppearance {
        metalness 0
      }
      geometry Box {
        size 0.1 0.1 0.0399
      }
    }
    Solid {
      translation -0.0859 -0.0853 0.02
      children [
        Shape {
          appearance PBRAppearance {
            metalness 0
          }
          geometry Mesh {
            url [
              "../RoboParts/topCylinder.STL"
            ]
            name "top cylinder"
          }
        }
      ]
      name "top"
      boundingObject Mesh {
        url [
          "../RoboParts/topCylinder.STL"
        ]
      }
      physics Physics {
        density 0.1
        centerOfMass [
          0 0 0
        ]
      }
    }
  ]
  name IS name
  model IS model
  boundingObject USE Body
  physics Physics {
  }
  controller IS controller
  battery [
    0
  ]
}
}

