#VRML_SIM R2023b utf8

EXTERNPROTO "https://raw.githubusercontent.com/cyberbotics/webots/R2023b/projects/objects/backgrounds/protos/TexturedBackground.proto"
EXTERNPROTO "https://raw.githubusercontent.com/cyberbotics/webots/R2023b/projects/objects/backgrounds/protos/TexturedBackgroundLight.proto"
EXTERNPROTO "https://raw.githubusercontent.com/cyberbotics/webots/R2023b/projects/objects/floors/protos/RectangleArena.proto"
EXTERNPROTO "https://raw.githubusercontent.com/cyberbotics/webots/R2023b/projects/objects/apartment_structure/protos/Wall.proto"
EXTERNPROTO "https://raw.githubusercontent.com/cyberbotics/webots/R2023b/projects/robots/gctronic/e-puck/protos/E-puckDistanceSensor.proto"

WorldInfo {
}
Viewpoint {
  orientation -0.2785436048717602 0.24620967223359833 0.9283287442946431 1.7672802232834943
  position 1.1256430821444678 -0.6649750540864601 0.33320554503729954
  follow "AutoNova"
  followType "Pan and Tilt Shot"
}
TexturedBackground {
}
TexturedBackgroundLight {
  castShadows FALSE
}
RectangleArena {
  translation -0.01 0 0
  floorSize 7 7
  floorAppearance PBRAppearance {
    baseColor 0.35 0.4 0.3
    roughness 1
    metalness 0
    normalMap ImageTexture {
      url [
        "https://raw.githubusercontent.com/cyberbotics/webots/R2023b/projects/appearances/protos/textures/parquetry/mosaic_parquetry_normal.jpg"
      ]
    }
    occlusionMap ImageTexture {
      url [
        "https://raw.githubusercontent.com/cyberbotics/webots/R2023b/projects/appearances/protos/textures/parquetry/mosaic_parquetry_occlusion.jpg"
      ]
    }
  }
}
Wall {
  translation -2.65 0.07 0
  size 0.01 5.04 0.1
}
Wall {
  translation 2.4 0.06 0
  name "wall(1)"
  size 0.01 5.04 0.1
}
Wall {
  translation -0.130008 2.59 0
  rotation 0 0 1 1.5707996938995747
  name "wall(2)"
  size 0.01 5.04 0.1
}
Wall {
  translation -1.39998 -2.46 0
  rotation 0 0 1 1.5707996938995747
  name "wall(3)"
  size 0.01 2.5 0.1
}
Wall {
  translation 1.25002 -2.46 0
  rotation 0 0 1 1.5707996938995747
  name "wall(4)"
  size 0.01 2.26 0.1
}
Pose {
  translation -0.5 2.6 0
  rotation 1 0 0 1.5707996938995747
  children [
    Shape {
      appearance Appearance {
        material Material {
          diffuseColor 0.972549 0.972549 0.972549
        }
      }
      geometry Mesh {
        url [
          "../3D_maze/evaluation_maze1.obj"
        ]
      }
    }
  ]
}
Pose {
  translation -0.5 2.6 0
  rotation 1 0 0 1.5707996938995747
  children [
    Shape {
      appearance Appearance {
        material Material {
          diffuseColor 1 0.333333 0
        }
      }
      geometry Mesh {
        url [
          "../3D_maze/evaluation_maze3.obj"
        ]
      }
    }
  ]
}
Robot {
  translation 1.0673191549983678 -0.193497124570206 0.01991085647143303
  rotation -2.5443800947770214e-08 6.684666796597321e-11 -0.9999999999999998 0.005095756222499305
  children [
    E-puckDistanceSensor {
      translation -0.060104 0.060104 0.025
      rotation 0.28108214909598983 0.6785993599532862 -0.6785983599527559 -2.593565307179586
      name "ps7"
    }
    E-puckDistanceSensor {
      translation -0.085 0 0.025
      rotation -2.4545692404262723e-06 0.7071077811834008 -0.7071057811840198 3.14159
      name "ps6"
    }
    E-puckDistanceSensor {
      translation -0.060104 -0.060104 0.025
      rotation 0.28108694479748086 -0.6785988667303209 0.6785968667307137 -2.593555307179586
      name "ps5"
    }
    E-puckDistanceSensor {
      translation 0 -0.085 0.025
      rotation -0.5773519358536056 0.5773509358537166 -0.5773479358540499 2.09439
      name "ps4"
    }
    E-puckDistanceSensor {
      translation 0.060104 -0.060104 0.025
      rotation -0.7745983069369637 0.44721317720959824 -0.44721117720880577 1.82347
      name "ps3"
    }
    E-puckDistanceSensor {
      translation 0.085 0 0.025
      rotation -0.9999999999931786 -1.2753299999913004e-06 3.4664999999763536e-06 1.57079
      name "ps2"
    }
    E-puckDistanceSensor {
      translation 0.060104 0.060104 0.025
      rotation -0.8628548176054536 -0.35740792444933384 0.3574089244491224 1.71777
      name "ps1"
    }
    E-puckDistanceSensor {
      translation 0 0.085 0.025
      rotation 0.5773476025217157 0.5773516025189619 -0.5773516025189619 -2.094395307179586
      name "ps0"
    }
    HingeJoint {
      jointParameters HingeJointParameters {
        position -1.3120270106968302e-12
        axis 0 1 0
        anchor 0 0.06 0.01
      }
      device [
        PositionSensor {
          name "left encoder"
        }
        RotationalMotor {
          name "left motor"
        }
      ]
      endPoint Solid {
        translation 0 0.06 0.01
        rotation 1 -4.184923660838354e-11 4.1849389363712775e-11 1.5707999999987055
        children [
          DEF wheel Shape {
            appearance PBRAppearance {
              baseColor 0 1 1
              metalness 0
            }
            geometry DEF wheel_geo Cylinder {
              height 0.009
              radius 0.03
            }
          }
        ]
        name "LeftWheel"
        boundingObject USE wheel
        physics Physics {
        }
        linearVelocity -2.944085579315311e-13 1.092914264492164e-15 -3.032124474265524e-16
        angularVelocity -4.2855020897605754e-14 -1.3116743530506802e-11 1.179293803191542e-12
      }
    }
    HingeJoint {
      jointParameters HingeJointParameters {
        position 1.2777659801797784e-12
        axis 0 1 0
        anchor 0 -0.06 0.01
      }
      device [
        PositionSensor {
          name "right encoder"
        }
        RotationalMotor {
          name "right motor"
        }
      ]
      endPoint Solid {
        translation 0 -0.06 0.01
        rotation -0.07804986893915082 0.7049484261742475 -0.7049510155982707 -2.9858093072697
        children [
          DEF wheel Shape {
            appearance PBRAppearance {
              baseColor 0 1 1
              metalness 0
            }
            geometry DEF wheel_geo Cylinder {
              height 0.009
              radius 0.03
            }
          }
        ]
        name "RightWheel"
        boundingObject USE wheel
        physics DEF physics_wh Physics {
        }
        linearVelocity 2.84820558950783e-13 -1.5636523003944068e-15 -6.381591235505942e-16
        angularVelocity 6.637562607571138e-14 1.2769288404541927e-11 1.1793029251714688e-12
      }
    }
    DEF Body Shape {
      appearance PBRAppearance {
        metalness 0
      }
      geometry Box {
        size 0.1 0.1 0.04
      }
    }
    Solid {
      translation -0.0859 -0.0853 0.019987
      children [
        Shape {
          appearance PBRAppearance {
            metalness 0
          }
          geometry Mesh {
            url [
              "../RoboParts/topCylinder.STL"
            ]
            name "top cylinder"
          }
        }
      ]
      name "top"
      boundingObject Mesh {
        url [
          "../RoboParts/topCylinder.STL"
        ]
      }
    }
  ]
  name "AutoNova"
  model "v1"
  boundingObject USE Body
  physics Physics {
  }
  battery [
    0
  ]
  linearVelocity -4.6806693919556135e-16 3.597003409388576e-17 2.0219603523553455e-17
  angularVelocity -5.8340195949694476e-15 -2.9196139039064173e-15 1.1793146198136753e-12
}
