#VRML_SIM R2023b utf8

EXTERNPROTO "https://raw.githubusercontent.com/cyberbotics/webots/R2023b/projects/objects/backgrounds/protos/TexturedBackground.proto"
EXTERNPROTO "https://raw.githubusercontent.com/cyberbotics/webots/R2023b/projects/objects/backgrounds/protos/TexturedBackgroundLight.proto"
EXTERNPROTO "https://raw.githubusercontent.com/cyberbotics/webots/R2023b/projects/objects/floors/protos/RectangleArena.proto"
EXTERNPROTO "https://raw.githubusercontent.com/cyberbotics/webots/R2023b/projects/objects/apartment_structure/protos/Wall.proto"

WorldInfo {
}
Viewpoint {
  orientation -0.3586922819531588 0.29929460142067105 0.8841733927390473 1.8702427298296853
  position 0.48147946841624156 -3.3108040302618944 2.737882839468095
}
TexturedBackground {
}
TexturedBackgroundLight {
}
RectangleArena {
  translation -0.01 0 0
  floorSize 7 7
  floorAppearance PBRAppearance {
    baseColor 0.12549 0.0862745 0.0627451
    roughness 1
    roughnessMap ImageTexture {
      url [
        "https://raw.githubusercontent.com/cyberbotics/webots/R2023b/projects/appearances/protos/textures/parquetry/mosaic_parquetry_roughness.jpg"
      ]
    }
    metalness 0
    normalMap ImageTexture {
      url [
        "https://raw.githubusercontent.com/cyberbotics/webots/R2023b/projects/appearances/protos/textures/parquetry/mosaic_parquetry_normal.jpg"
      ]
    }
    occlusionMap ImageTexture {
      url [
        "https://raw.githubusercontent.com/cyberbotics/webots/R2023b/projects/appearances/protos/textures/parquetry/mosaic_parquetry_occlusion.jpg"
      ]
    }
  }
}
Wall {
  translation -2.65 0.07 0
  size 0.01 5.04 0.1
}
Wall {
  translation 2.4 0.06 0
  name "wall(1)"
  size 0.01 5.04 0.1
}
Wall {
  translation -0.130008 2.59 0
  rotation 0 0 1 1.5707996938995747
  name "wall(2)"
  size 0.01 5.04 0.1
}
Wall {
  translation -1.39998 -2.46 0
  rotation 0 0 1 1.5707996938995747
  name "wall(3)"
  size 0.01 2.5 0.1
}
Wall {
  translation 1.25002 -2.46 0
  rotation 0 0 1 1.5707996938995747
  name "wall(4)"
  size 0.01 2.26 0.1
}
Pose {
  translation -0.5 2.6 0
  rotation 1 0 0 1.5707996938995747
  children [
    Shape {
      appearance Appearance {
        material Material {
          diffuseColor 0.972549 0.972549 0.972549
        }
      }
      geometry Mesh {
        url [
          "../3D_maze/evaluation_maze1.obj"
        ]
      }
    }
  ]
}
Pose {
  translation -0.5 2.6 0
  rotation 1 0 0 1.5707996938995747
  children [
    Shape {
      appearance Appearance {
        material Material {
          diffuseColor 1 0.333333 0
        }
      }
      geometry Mesh {
        url [
          "../3D_maze/evaluation_maze3.obj"
        ]
      }
    }
  ]
}
Robot {
  translation 0.03 0.0575 0.03
  rotation 0 1 0 1.62771e-06
  children [
    HingeJoint {
      jointParameters HingeJointParameters {
        position 2.464267769777152e-08
      }
      device [
        PositionSensor {
          name "posL"
        }
        RotationalMotor {
          name "motL"
        }
      ]
      endPoint Solid {
        translation -0.06099999999935347 -1.0344618670003168e-14 -2.78149744039474e-07
        rotation 1.9247231761800903e-09 -0.9999999999999999 -1.924720567061186e-09 1.5707953315197476
        children [
          DEF wheel Shape {
            appearance PBRAppearance {
              baseColor 0 1 1
              metalness 0
            }
            geometry Cylinder {
              height 0.009
              radius 0.03
            }
          }
        ]
        name "LeftWheel"
        boundingObject USE wheel
        physics Physics {
        }
      }
    }
    HingeJoint {
      jointParameters HingeJointParameters {
        position -3.829343962272654e-11
      }
      device [
        DEF posR PositionSensor {
        }
        RotationalMotor {
          name "motR"
        }
      ]
      endPoint Solid {
        translation 0.05899999999999998 0 0
        rotation -5.7440218000987984e-11 -0.9999999999999999 5.744015943408982e-11 1.5707953071795866
        children [
          DEF wheel Shape {
            appearance PBRAppearance {
              baseColor 0 1 1
              metalness 0
            }
            geometry DEF wheel_geo Cylinder {
              height 0.009
              radius 0.03
            }
          }
        ]
        name "RightWheel"
        boundingObject USE wheel
        physics DEF physics_wh Physics {
        }
      }
    }
    DEF Body Shape {
      appearance PBRAppearance {
        metalness 0
      }
      geometry Box {
        size 0.1 0.1 0.04
      }
    }
    Solid {
      translation 0.08500000001059471 -0.085 0.01998699105674065
      rotation -2.994708204376036e-22 -1.497354102188018e-22 1 1.5708
      children [
        Shape {
          appearance PBRAppearance {
            metalness 0
          }
          geometry Mesh {
            url [
              "../RoboParts/topCylinder.STL"
            ]
            name "top cylinder"
          }
        }
      ]
      name "top"
      boundingObject Mesh {
        url [
          "../RoboParts/topCylinder.STL"
        ]
      }
      physics Physics {
      }
      linearVelocity 0 0 -6.850363494648173e-17
    }
  ]
  name "AutoNova"
  model "v1"
  battery [
    0
  ]
}
